<?xml version="1.0" ?>
<sdf version="1.8">
  <world name="default">
    
    <physics name="1ms" type="ignored">
      <max_step_size>0.001</max_step_size>
      <real_time_factor>1.0</real_time_factor>
    </physics>

    <light type="directional" name="sun">
      <cast_shadows>true</cast_shadows>
      <pose>0 0 10 0 0 0</pose>
      <diffuse>0.8 0.8 0.8 1</diffuse>
      <specular>0.2 0.2 0.2 1</specular>
      <direction>-0.5 0.1 -0.9</direction>
    </light>

    <model name="ground_plane">
      <static>true</static>
      <link name="link">
        <collision name="collision">
          <geometry><plane><normal>0 0 1</normal><size>100 100</size></plane></geometry>
        </collision>
        <visual name="visual">
          <geometry><plane><normal>0 0 1</normal><size>100 100</size></plane></geometry>
          <material>
            <ambient>0.8 0.8 0.8 1</ambient>
            <diffuse>0.8 0.8 0.8 1</diffuse>
          </material>
        </visual>
      </link>
    </model>


    <model name='crawler_robot'>
      <pose>0 0 0.2 0 0 0</pose> <link name='base_link'>
        <inertial>
          <mass>2.0</mass>
          <inertia>
            <ixx>0.1</ixx> <ixy>0</ixy> <ixz>0</ixz>
            <iyy>0.1</iyy> <iyz>0</iyz> <izz>0.1</izz>
          </inertia>
        </inertial>
        <visual name='base_visual'>
          <geometry>
            <box><size>0.25 0.3 0.1</size></box>
          </geometry>
          <material>
            <ambient>0.3 0.3 0.3 1</ambient>
            <diffuse>0.3 0.3 0.3 1</diffuse>
          </material>
        </visual>
        <collision name='base_collision'>
          <geometry>
            <box><size>0.25 0.3 0.1</size></box>
          </geometry>
        </collision>
        
        <sensor name="imu_sensor" type="imu">
          <always_on>1</always_on>
          <update_rate>100</update_rate>
          <visualize>true</visualize>
        </sensor>

        

      </link>


      <link name='crawler_left_visual'>
        <pose>-0.26 0.24 -0.1 0 0 0</pose>
        <visual name='visual'>
          <geometry>
            <mesh>
              <uri>file:///home/ubuntu/projects/slam/crawler.stl</uri>
              <scale>0.001 0.001 0.001</scale>
            </mesh>
          </geometry>
          <material>
            <ambient>0.8 0.8 0.8 1</ambient>
            <diffuse>0.8 0.8 0.8 1</diffuse>
          </material>
          </visual>
      </link>

      <link name='crawler_right_visual'>
        <pose>-0.26 -0.15 -0.1 0 0 0</pose>
        <visual name='visual'>
          <geometry>
            <mesh>
              <uri>file:///home/ubuntu/projects/slam/crawler.stl</uri>
              <scale>0.001 0.001 0.001</scale>
            </mesh>
          </geometry>
          <material>
            <ambient>0.8 0.8 0.8 1</ambient>
            <diffuse>0.8 0.8 0.8 1</diffuse>
          </material>
           </visual>
      </link>

      <joint name='fixed_left_visual' type='fixed'>
        <parent>base_link</parent>
        <child>crawler_left_visual</child>
      </joint>

      <joint name='fixed_right_visual' type='fixed'>
        <parent>base_link</parent>
        <child>crawler_right_visual</child>
      </joint>


      <link name='left_wheel_ghost'>
        <pose>0 0.24 -0.05 -1.5707 0 0</pose>
        <inertial><mass>0.5</mass><inertia><ixx>0.01</ixx><iyy>0.01</iyy><izz>0.01</izz></inertia></inertial>
        <collision name='col_left'>
          <geometry><cylinder><radius>0.06</radius><length>0.05</length></cylinder></geometry>
          <surface><friction><ode><mu>1.0</mu><mu2>1.0</mu2></ode></friction></surface>
        </collision>
      </link>

      <link name='right_wheel_ghost'>
         <pose>0 -0.15 -0.05 -1.5707 0 0</pose>
        <inertial><mass>0.5</mass><inertia><ixx>0.01</ixx><iyy>0.01</iyy><izz>0.01</izz></inertia></inertial>
        <collision name='col_right'>
          <geometry><cylinder><radius>0.06</radius><length>0.05</length></cylinder></geometry>
          <surface><friction><ode><mu>1.0</mu><mu2>1.0</mu2></ode></friction></surface>
        </collision>
      </link>

      <joint name='left_wheel_joint' type='revolute'>
        <parent>base_link</parent>
        <child>left_wheel_ghost</child>
        <axis><xyz>0 0 1</xyz></axis>
      </joint>

      <joint name='right_wheel_joint' type='revolute'>
        <parent>base_link</parent>
        <child>right_wheel_ghost</child>
        <axis><xyz>0 0 1</xyz></axis>
      </joint>

      <plugin
        filename="gz-sim-diff-drive-system"
        name="gz::sim::systems::DiffDrive">
        <left_joint>left_wheel_joint</left_joint>
        <right_joint>right_wheel_joint</right_joint>
        <wheel_separation>0.39</wheel_separation> <wheel_radius>0.06</wheel_radius>
        <odom_publish_frequency>1</odom_publish_frequency>
      </plugin>

    </model>
  </world>
</sdf>
